Workbook
Name Slicer_product_name: #N/A

Sheet product_sales
A1: product_name | B1: total_sales_2023 | C1: total_sales_2024 | D1: growth_pct
A2: Pet Treats | B2: 105226.7 | C2: 146780.67 | D2: 139
A3: Vitamins | B3: 122690.17 | C3: 138131.84 | D3: 113
A4: Toilet Cleaner | B4: 82171.41 | C4: 117666.07 | D4: 143
A5: Dish Soap | B5: 78935.33 | C5: 105505.88 | D5: 134
A6: Bread | B6: 84624.73 | C6: 100226.37 | D6: 118
A7: Cough Syrup | B7: 106435.49 | C7: 97134.49 | D7: 91
A8: Baby Wipes | B8: 75065.06 | C8: 83703.35 | D8: 112
A9: Cat Food | B9: 91000.1 | C9: 75596.29 | D9: 83
A10: Lotion | B10: 68798.71 | C10: 67601.71 | D10: 98
A11: Eggs | B11: 70025.29 | C11: 67371.54 | D11: 96

Sheet category_sales
A1: category | B1: total_sales_2023 | C1: total_sales_2024 | D1: growth_pct
A2: Dairy & Breakfast | B2: 316645.53 | C2: 322576.66 | D2: 102
A3: Pharmacy | B3: 302638.92 | C3: 289729.65 | D3: 96
A4: Pet Care | B4: 254026.02 | C4: 285862.73 | D4: 113

Sheet growth_percent
A1: product_name | B1: total_sales_2023 | C1: total_sales_2024 | D1: growth | E1: growth_percentage
A2: Frozen Vegetables | B2: 21922.4 | C2: 37243.17 | D2: 170 | E2: =D2-100 -> 70
A3: Toilet Cleaner | B3: 82171.41 | C3: 117666.07 | D3: 143 | E3: =D3-100 -> 43
A4: Pet Treats | B4: 105226.7 | C4: 146780.67 | D4: 139 | E4: =D4-100 -> 39
A5: Salt | B5: 19332.81 | C5: 26763.45 | D5: 138 | E5: =D5-100 -> 38
A6: Detergent | B6: 25527.51 | C6: 34438.05 | D6: 135 | E6: =D6-100 -> 35
A7: Chocolates | B7: 21241.96 | C7: 28377.96 | D7: 134 | E7: =D7-100 -> 34
A8: Dish Soap | B8: 78935.33 | C8: 105505.88 | D8: 134 | E8: =D8-100 -> 34
A9: Curd | B9: 33106.39 | C9: 40948.69 | D9: 124 | E9: =D9-100 -> 24
A10: Wheat Flour | B10: 41569.56 | C10: 51222.1 | D10: 123 | E10: =D10-100 -> 23
A11: Carrots | B11: 55245.54 | C11: 65253.71 | D11: 118 | E11: =D11-100 -> 18

Sheet pivot_tables
A2: product name | B2: 2023 | C2: 2024
A3: Baby Wipes | B3: 75065.06 | C3: 83703.35
A4: Bread | B4: 84624.73 | C4: 100226.37
A5: Cat Food | B5: 91000.1 | C5: 75596.29
A6: Cough Syrup | B6: 106435.49 | C6: 97134.49
A7: Dish Soap | B7: 78935.33 | C7: 105505.88
A8: Eggs | B8: 70025.29 | C8: 67371.54
A9: Lotion | B9: 68798.71 | C9: 67601.71
A10: Pet Treats | B10: 105226.7 | C10: 146780.67
A11: Toilet Cleaner | B11: 82171.41 | C11: 117666.07
A12: Vitamins | B12: 122690.17 | C12: 138131.84
A13: Grand Total | B13: 884972.99 | C13: 999718.21
A16: category | B16: 2023 | C16: 2024
A17: Dairy & Breakfast | B17: 316645.53 | C17: 322576.66
A18: Pet Care | B18: 254026.02 | C18: 285862.73
A19: Pharmacy | B19: 302638.92 | C19: 289729.65
A20: Grand Total | B20: 873310.47 | C20: 898169.04
A23: product name | B23: 2023 | C23: 2024
A24: Carrots | B24: 55245.54 | C24: 65253.71
A25: Chocolates | B25: 21241.96 | C25: 28377.96
A26: Curd | B26: 33106.39 | C26: 40948.69
A27: Detergent | B27: 25527.51 | C27: 34438.05
A28: Dish Soap | B28: 78935.33 | C28: 105505.88
A29: Frozen Vegetables | B29: 21922.4 | C29: 37243.17
A30: Pet Treats | B30: 105226.7 | C30: 146780.67
A31: Salt | B31: 19332.81 | C31: 26763.45
A32: Toilet Cleaner | B32: 82171.41 | C32: 117666.07
A33: Wheat Flour | B33: 41569.56 | C33: 51222.1
A34: Grand Total | B34: 484279.61 | C34: 654199.75
A37: product_name | B37: Sum of growth percentage
A38: Carrots | B38: 18
A39: Chocolates | B39: 34
A40: Curd | B40: 24
A41: Detergent | B41: 35
A42: Dish Soap | B42: 34
A43: Frozen Vegetables | B43: 70
A44: Pet Treats | B44: 39
A45: Salt | B45: 38
A46: Toilet Cleaner | B46: 43
A47: Wheat Flour | B47: 23
...

Sheet dashboard
A1: Most Selling Product Types & Product Categories in 2024, and Product Types with Most Growth From 2023 to 2024
R11: MOST SELLING PRODUCTS
R12: 1st
R13: =_xlfn.CONCAT("Product : ",product_sales!A2) -> Product : Pet Treats
R14: =_xlfn.CONCAT("Sales in 2024 : ",product_sales!C2) -> Sales in 2024 : 146780.67
R15: =_xlfn.CONCAT("Sales Growth : ",product_sales!D2-100,"%") -> Sales Growth : 39%
R16: 2nd
R17: =_xlfn.CONCAT("Product : ",product_sales!A3) -> Product : Vitamins
R18: =_xlfn.CONCAT("Sales in 2024 : ",product_sales!C3) -> Sales in 2024 : 138131.84
R19: =_xlfn.CONCAT("Sales Growth : ",product_sales!D3-100,"%") -> Sales Growth : 13%
R20: 3rd
R21: =_xlfn.CONCAT("Product : ",product_sales!A4) -> Product : Toilet Cleaner
R22: =_xlfn.CONCAT("Sales in 2024 : ",product_sales!C3) -> Sales in 2024 : 138131.84
R23: =_xlfn.CONCAT("Sales Growth : ",product_sales!D4-100,"%") -> Sales Growth : 43%
R31: PRODUCTS
R32: =_xlfn.CONCAT(growth_percent!A2," : ",growth_percent!E2,"%") -> Frozen Vegetables : 70%
R33: =_xlfn.CONCAT(growth_percent!A3," : ",growth_percent!E3,"%") -> Toilet Cleaner : 43%
R34: =_xlfn.CONCAT(growth_percent!A4," : ",growth_percent!E4,"%") -> Pet Treats : 39%
R35: =_xlfn.CONCAT(growth_percent!A5," : ",growth_percent!E5,"%") -> Salt : 38%
R36: =_xlfn.CONCAT(growth_percent!A6," : ",growth_percent!E6,"%") -> Detergent : 35%
R37: =_xlfn.CONCAT(growth_percent!A7," : ",growth_percent!E7,"%") -> Chocolates : 34%
R38: =_xlfn.CONCAT(growth_percent!A8," : ",growth_percent!E8,"%") -> Dish Soap : 34%
R39: =_xlfn.CONCAT(growth_percent!A9," : ",growth_percent!E9,"%") -> Curd : 24%
R40: =_xlfn.CONCAT(growth_percent!A10," : ",growth_percent!E10,"%") -> Wheat Flour : 23%
R41: =_xlfn.CONCAT(growth_percent!A11," : ",growth_percent!E11,"%") -> Carrots : 18%
